2020-07-02 14:05:33,069 INFO: Flask_Blog startup [/home/derek/Development/coding_temple/week_05/flask-blog/app/__init__.py:78]
2020-07-02 14:08:18,244 ERROR: Exception on /account/register [POST] [/home/derek/Development/coding_temple/week_05/flask-blog/venv/lib/python3.6/site-packages/flask/app.py:1892]
Traceback (most recent call last):
  File "/home/derek/Development/coding_temple/week_05/flask-blog/venv/lib/python3.6/site-packages/sqlalchemy/engine/base.py", line 1278, in _execute_context
    cursor, statement, parameters, context
  File "/home/derek/Development/coding_temple/week_05/flask-blog/venv/lib/python3.6/site-packages/sqlalchemy/engine/default.py", line 593, in do_execute
    cursor.execute(statement, parameters)
psycopg2.errors.UniqueViolation: duplicate key value violates unique constraint "user_email_key"
DETAIL:  Key (email)=(derekh@codingtemple.com) already exists.


The above exception was the direct cause of the following exception:

Traceback (most recent call last):
  File "/home/derek/Development/coding_temple/week_05/flask-blog/venv/lib/python3.6/site-packages/flask/app.py", line 2447, in wsgi_app
    response = self.full_dispatch_request()
  File "/home/derek/Development/coding_temple/week_05/flask-blog/venv/lib/python3.6/site-packages/flask/app.py", line 1952, in full_dispatch_request
    rv = self.handle_user_exception(e)
  File "/home/derek/Development/coding_temple/week_05/flask-blog/venv/lib/python3.6/site-packages/flask/app.py", line 1821, in handle_user_exception
    reraise(exc_type, exc_value, tb)
  File "/home/derek/Development/coding_temple/week_05/flask-blog/venv/lib/python3.6/site-packages/flask/_compat.py", line 39, in reraise
    raise value
  File "/home/derek/Development/coding_temple/week_05/flask-blog/venv/lib/python3.6/site-packages/flask/app.py", line 1950, in full_dispatch_request
    rv = self.dispatch_request()
  File "/home/derek/Development/coding_temple/week_05/flask-blog/venv/lib/python3.6/site-packages/flask/app.py", line 1936, in dispatch_request
    return self.view_functions[rule.endpoint](**req.view_args)
  File "/home/derek/Development/coding_temple/week_05/flask-blog/app/blueprints/account/routes.py", line 51, in register
    db.session.commit()
  File "/home/derek/Development/coding_temple/week_05/flask-blog/venv/lib/python3.6/site-packages/sqlalchemy/orm/scoping.py", line 163, in do
    return getattr(self.registry(), name)(*args, **kwargs)
  File "/home/derek/Development/coding_temple/week_05/flask-blog/venv/lib/python3.6/site-packages/sqlalchemy/orm/session.py", line 1042, in commit
    self.transaction.commit()
  File "/home/derek/Development/coding_temple/week_05/flask-blog/venv/lib/python3.6/site-packages/sqlalchemy/orm/session.py", line 504, in commit
    self._prepare_impl()
  File "/home/derek/Development/coding_temple/week_05/flask-blog/venv/lib/python3.6/site-packages/sqlalchemy/orm/session.py", line 483, in _prepare_impl
    self.session.flush()
  File "/home/derek/Development/coding_temple/week_05/flask-blog/venv/lib/python3.6/site-packages/sqlalchemy/orm/session.py", line 2523, in flush
    self._flush(objects)
  File "/home/derek/Development/coding_temple/week_05/flask-blog/venv/lib/python3.6/site-packages/sqlalchemy/orm/session.py", line 2664, in _flush
    transaction.rollback(_capture_exception=True)
  File "/home/derek/Development/coding_temple/week_05/flask-blog/venv/lib/python3.6/site-packages/sqlalchemy/util/langhelpers.py", line 69, in __exit__
    exc_value, with_traceback=exc_tb,
  File "/home/derek/Development/coding_temple/week_05/flask-blog/venv/lib/python3.6/site-packages/sqlalchemy/util/compat.py", line 178, in raise_
    raise exception
  File "/home/derek/Development/coding_temple/week_05/flask-blog/venv/lib/python3.6/site-packages/sqlalchemy/orm/session.py", line 2624, in _flush
    flush_context.execute()
  File "/home/derek/Development/coding_temple/week_05/flask-blog/venv/lib/python3.6/site-packages/sqlalchemy/orm/unitofwork.py", line 422, in execute
    rec.execute(self)
  File "/home/derek/Development/coding_temple/week_05/flask-blog/venv/lib/python3.6/site-packages/sqlalchemy/orm/unitofwork.py", line 589, in execute
    uow,
  File "/home/derek/Development/coding_temple/week_05/flask-blog/venv/lib/python3.6/site-packages/sqlalchemy/orm/persistence.py", line 245, in save_obj
    insert,
  File "/home/derek/Development/coding_temple/week_05/flask-blog/venv/lib/python3.6/site-packages/sqlalchemy/orm/persistence.py", line 1136, in _emit_insert_statements
    statement, params
  File "/home/derek/Development/coding_temple/week_05/flask-blog/venv/lib/python3.6/site-packages/sqlalchemy/engine/base.py", line 1014, in execute
    return meth(self, multiparams, params)
  File "/home/derek/Development/coding_temple/week_05/flask-blog/venv/lib/python3.6/site-packages/sqlalchemy/sql/elements.py", line 298, in _execute_on_connection
    return connection._execute_clauseelement(self, multiparams, params)
  File "/home/derek/Development/coding_temple/week_05/flask-blog/venv/lib/python3.6/site-packages/sqlalchemy/engine/base.py", line 1133, in _execute_clauseelement
    distilled_params,
  File "/home/derek/Development/coding_temple/week_05/flask-blog/venv/lib/python3.6/site-packages/sqlalchemy/engine/base.py", line 1318, in _execute_context
    e, statement, parameters, cursor, context
  File "/home/derek/Development/coding_temple/week_05/flask-blog/venv/lib/python3.6/site-packages/sqlalchemy/engine/base.py", line 1512, in _handle_dbapi_exception
    sqlalchemy_exception, with_traceback=exc_info[2], from_=e
  File "/home/derek/Development/coding_temple/week_05/flask-blog/venv/lib/python3.6/site-packages/sqlalchemy/util/compat.py", line 178, in raise_
    raise exception
  File "/home/derek/Development/coding_temple/week_05/flask-blog/venv/lib/python3.6/site-packages/sqlalchemy/engine/base.py", line 1278, in _execute_context
    cursor, statement, parameters, context
  File "/home/derek/Development/coding_temple/week_05/flask-blog/venv/lib/python3.6/site-packages/sqlalchemy/engine/default.py", line 593, in do_execute
    cursor.execute(statement, parameters)
sqlalchemy.exc.IntegrityError: (psycopg2.errors.UniqueViolation) duplicate key value violates unique constraint "user_email_key"
DETAIL:  Key (email)=(derekh@codingtemple.com) already exists.

[SQL: INSERT INTO "user" (name, email, password) VALUES (%(name)s, %(email)s, %(password)s) RETURNING "user".id]
[parameters: {'name': 'derekhawkins_tech', 'email': 'derekh@codingtemple.com', 'password': 'pbkdf2:sha256:150000$TUQNrb6F$ed2eb6c56660005a25bb99ff4a8e6dcc84137de234b44210cfa649b5861c4e32'}]
(Background on this error at: http://sqlalche.me/e/13/gkpj)
